---
layout:     post
title:      Promise的基本用法
subtitle:   简单介绍了JS中异步的问题，以及Promise的基本用法
date:       2018-10-20
author:     Tank
header-img: img/post-bg-js-version.jpg
catalog: true
tags:
    - 前端
    - Promise
---

> 本文首次发布于 [Tank's Blog](https://spicycrayfish.github.io/), 作者 [@谭轲](http://github.com/Spicycrayfish) ,转载请保留原文链接.



# 关于回调和回调的问题

`JavaScript`  包含大量异步操作，异步操作的常见语法有：

1. 事件监听与响应

   ```javascript
   document.getElementById('button').addEventListener('click', start, false);
   
   function start() {
       alert('start');
   }
   ```


2. 回调

   ```javascript
   // 比较常见的有 ajax 请求
   $.ajax('http://google.com', {
       success: function(res) {
           console.log(res)
       }
   });
   ```



生产环境中大量操作都依赖回调函数，带来异步回调的问题，比如 **回调地狱**：

```javascript
a(function(resA) {
    b(resA, function(resA) {
        c(resB, function(resB) {
            d(resC, function(resC) {
                console.log(resD)
            })
        })
    })
})
```

**回调地狱** 使得后期代码结构混乱很难维护，除此之外回调还有更深层次的问题：

```javascript
const fs = require('fs')
const path = require('path')

function findLargest(dir, callback) {
    fs.readdir(dir, function(err, files) {
        if(err) return callback(err)	// 问题1，无法正常使用 try catch 错误处理机制
        let count = files.length	// 问题2，变量可能被无关函数访问和修改
        let errored = false
        let stats = []
        files.forEach(function(file) {
            fs.stat(path.join(dir, file), function(err, stat) {
                if(errored) return	// 问题1
                if(err) {
                    errored = true
                    return callback(err)
                }
                stats.push(stat)	// 问题2
                
                if(--count === 0) {
                    let largest = stats
                    	.filter(function(stat) { return stat.isFIle() })
                        .reduce(function(prev, next) {
							if(prev.size > next.size) return prev
                        })
                    callback(null, files[stats.indexOf(largest)])
                }
            })
        })
    })
}
```



1. 异步回调中无法正常使用 `try catch` 错误处理机制，只能等函数执行完成后在其回调函数中接收可能发生的错误；（异步回调函数会在一个新的栈里运行，在新的栈中无法获取之前的栈的信息，之前的栈也无法捕获新的栈抛出的错误，导致无法使用 `try catc` 机制处理可能发生的错误）
2. 在更高层作用域声明的变量可能被其它的函数访问和修改，导致变量异常发生错误；（无法判断异步何时完成，只能在更高级的作用域中声明变量交给内层使用，导致可能出现变量操作错误导致bug）



回调的四个问题：

1. 嵌套层次深，后期代码难以维护；
2. 无法正常使用 `return` 和 `throw`；
3. 无法正常检索堆栈信息；
4. 多个回调之间难以建立联系。



# Promise 详解

## `Promise` 的使用

```javascript
new Promise(
    // 执行器 executor
    function (resolve, reject) {
        // 一段耗时很长的异步操作
        
        resolve(); // 数据处理完成
        
        reject(); // 数据处理出错
    }
).then(function A() {
    // 成功，下一步
}, function B() {
    // 失败，做对应处理
})
```

初始化一个 `Promise` 实例，并传一个参数，该参数是一个函数，称之为执行器；

执行器函数接受两个参数：`resolve` 和 `reject`，将耗时长的异步操作放在执行器中让其执行；

当执行器执行完该操作后会进行判断，如果数据处理操作成功了，就执行 `resolve` 方法，如果处理出错了，即执行 `reject` 方法；

`resolve` 或 `reject` 这两个函数调用之后，会改变当前这个 `Promise` 实例的状态，`Promise` 实例状态改变后，就会去调用 `then` 函数里对应的处理函数；

如果之前调用的 `resolve` ，则会调用 `then` 函数里第一个参数里的函数，如果之前调用的是 `reject` 或者抛出一个错误，就会执行 `then` 函数里第二个参数里的函数。



* `Promise` 是一个代理对象，它和原本要进行的操作并无关系，我们只是把原本要执行的操作放进执行器里。
* `Promise` 通过引入一个回调，以此将其它的回调展开，全部变成基于 `Promise` 的回调，避免更多的回调。



## `Promise` 的状态

`Promise` 有3个状态：

* `pending` [待定] 初始状态
* `fulfilled` [实现] 操作成功
* `reject` [被否决] 操作失败

`Promise` 状态发生改变后，就会触发 `.then()` 里面的响应函数处理后续步骤。

`Promise` 状态一经改变，不会再变。

`Promise` 实例一经创建，执行器立即执行。



## 简单示例

#### 定时执行：

```javascript
new Promise(resolve => {
    setTimeout(() => {
        resolve('hello')
    }, 2400)
}).then( value => {
    console.log(value)
})

// 2.4秒后打印 hello
```



#### 分两次，顺序依次执行（解决嵌套问题）：

```javascript
new Promise(resolve => {
    setTimeout(() => {
        resolve('hello')
    }, 2400)
}).then(value => {
    console.log(value)
    return new Promise(resolve => {
        setTimeout(() => {
            resolve('world')
        }, 2400)
    })
}).then(value => {
    console.log(value)
})

// 2.4秒后打印 hello，再过2.4秒后打印 world；
```



#### `Promise` 完成后追加 `.then()` ：

```javascript
let promise = new Promise(resolve => {
    setTimeout(() => {
        console.log('the promise fulfilled')
        resolve('then')
    }, 1000)
})

setTimeout(() => {
    promise.then(value => {
        console.log(value)
    })
}, 3000)

// 1秒后打印 the promise fulfilled，再过2秒后打印 then
```

`Promise` 作为队列的重要特性，生成 `Promise` 队列后，可追续任意多的 `.then()`，不管 `Promise` 状态如何，后面的 `.then()` 都会接收到前面 `Promise` 返回的值。



####`.then()` 里不返回 `Promise`

```javascript
new Promise(resolve => {
    setTimeout(() => {
        resolve('hello')
    }, 2400)
}).then(value => {
    console.log(value)
    (function() {
        return new Promise(resolve => {
        	setTimeout(() => {
                console.log('everyone')
        	    resolve('world')
       	 	}, 2400)
    	})
    }())
    return false
}).then(value => {
    console.log(value)
    console.log('everybody')
})

// 2.4秒后打印 hello false everybody，再过2.4秒后打印 everyone；
```



## `.then()`

* `.then()` 接收两个函数作为参数，分别代表 `fulfilled` 和 `rejected`；
* `.then()` 返回一个新的 `Promise` 实例，所以它可以链式调用；
* 当前面的 `Promise` 状态改变时，`.then()` 根据其最终状态，选择特定的状态响应函数执行；
* 状态响应函数可以返回新的 `Promise`，或其它值；
* 如果返回新的 `Promise`，那么下一级的 `.then()` 会在新的 `Promise` 状态改变之后执行；
* 如果返回其它任何值，则会立刻执行下一级 `.then()`



#### `.then()` 的嵌套

```javascript
new Promise(resolve => {
    console.log('step 1')
    setTimeout(() => {
        resolve(100)
    }, 1000)
}).then(value => {
    return new Promise(resolve => {
        console.log('step 1-1')
        setTimeout(() => {
            resolve(110)
        }, 1000)
    }).then(value => {
        console.log('step 1-2')
        return value
    }).then(value => {
        console.log('step 1-3')
        return value
    })
}).then(value => {
    console.log(value)
    console.log('step 2')
})

// step 1
// step 1-1
// step 1-2
// step 1-3
// 110
// step 2
```

因为 `.then()` 返回的还是 `Promise` 实例，所以嵌套中外层的 `.then()` 会等到里面的 `.then()` 执行完之后再执行外面的。上述代码执行效果与下面的完成一样：

```javascript
new Promise(resolve => {
    console.log('step 1')
    setTimeout(() => {
        resolve(100)
    }, 1000)
}).then(value => {
    return new Promise(resolve => {
        console.log('step 1-1')
        setTimeout(() => {
            resolve(110)
        }, 1000)
    })
}).then(value => {
    console.log('step 1-2')
    return value
}).then(value => {
    console.log('step 1-3')
    return value
}).then(value => {
    console.log(value)
    console.log('step 2')
})

// step 1
// step 1-1
// step 1-2
// step 1-3
// 110
// step 2
```

在 `Promise` 的使用过程中应避免前一段代码的嵌套形式的结构，尽量使用下面这种队列形式，便于阅读。



#### 判断下面几个 `Promise` 的区别

假设 `doSomething` 和 `DoSomethingElse` 返回的都是 `Promise` 实例，下面四段代码有什么区别：

```javascript
// #1
doSomething().then(function() {
    return doSomethingElse()
})

// #2
doSomething().then(function() {
    doSomethingElse()
})

// #3
doSomething().then(doSomethingElse())

// #4
doSomething().then(doSomethingElse)
```

问题一：

```javascript
doSomething().then(function() {
    return doSomethingElse()
}).then(findHandle)

// doSomething
// |----------|
//             doSomethingElse(undefined)
//			   |----------|
//						  findHandle(resultOfSomethingElse)
//						  |----------|
```

问题二：

```javascript
doSomething().then(function() {
    doSomethingElse()
}).then(findHandle)

// doSomething
// |----------|
//             doSomethingElse(undefined)
//			   |----------|
//             findHandle(undefined)
//			   |----------|
```

问题三：

```javascript
doSomething()
	.then(doSomethingElse())
	.then(findHandle)

// doSomething
// |----------|
// doSomethingElse(undefined)
// |--------------------|
//             findHandle(resultOfDoSomething)
//			   |----------|
```

问题四：

```javascript
doSomething()
	.then(doSomethingElse)
	.then(findHandle)

// doSomething
// |----------|
//             doSomethingElse(resultOfDoSomething)
//			   |----------|
//						  findHandle(resultOfSomethingElse)
//						  |----------|
```



## 错误处理

`Promise` 会自动捕获内部异常，并交给 `rejected` 响应函数处理。

即在 `Promise` 执行器中如果抛出错误，`Promise` 的状态就会改为 `rejected`，之后会调用 `rejected` 函数去处理，也会向后面寻找 `catch` 函数的响应函数去处理。

代码示例（catch）：

```javascript
new Promise(resolve => {
    setTimeout(() => {
        throw new Error('error test')
    }, 1000)
}).then(value => {
    console.log(value)
}).catch(error => {
    console.log(error.message)
})
```

代码示例（reject）：

```javascript
new Promise(resolve => {
    setTimeout(() => {
        reject('error test')
        // 也可抛出错误 让 reject 函数捕获
        // throw new Error('error test')
    }, 1000)
}).then(value => {
    console.log(value)
}, value => {
    console.log('error: ', value)
})
```

错误处理的两种做法：

1. `reject('错误信息').then(null, message => {})`
2. `throw new Error('错误信息').catch(message => {})`

> 推荐使用第二种，更加清晰好读，并且可以捕获前面的错误。



#### 错误和 `then` 连用

示例代码：

```javascript
new Promise(resolve => {
    setTimeout(() => {
        resolve()
    }, 1000)
}).then(() => {
    console.log('start')
    throw new Error('error test')
}).catch(err => {
    console.log('catch: ', err);
    
    // 下一行注释中的代码将引发不同的走向
    // throw new Error('another error')
}).then(() => {
    console.log('arrive here')
}).then(() => {
    console.log('... and here')
}).catch(err => {
    console.log('last catch: ', err)
})

// 打印结果
// start
// catch: Error: error test
// arrive here
// ... and here

// 如果取消注释，在 catch 中抛出错误，则会跳过后面两个 then 里面的函数，执行最后的 catch 里面的函数，所以取消注释后的打印结果为：
// catch: Error: error test
// last catch: Error: another error
```

`catch` 也会返回 `Promise` 实例，如果在 `catch` 中没有抛出错误，则 `catch` 返回的 `Promise` 的状态是 `fulfilled`。



> 注意：建议在所有队列最后都加上 `catch()`，以避免漏掉错误处理造成意外问题。

